[
  {
    "cmd": [],
    "name": "RECIPE CRASH (Uncaught exception)",
    "~followup_annotations": [
      "@@@STEP_EXCEPTION@@@",
      "The recipe has crashed at point 'Uncaught exception'!",
      "",
      "Traceback (most recent call last):",
      "  File \"RECIPE_REPO[recipe_engine]/recipe_engine/internal/engine.py\", in run_steps",
      "    raw_result = recipe_obj.run_steps(api, engine)",
      "  File \"RECIPE_REPO[recipe_engine]/recipe_engine/internal/recipe_deps.py\", in run_steps",
      "    properties_def, api=api)",
      "  File \"RECIPE_REPO[recipe_engine]/recipe_engine/internal/property_invoker.py\", in invoke_with_properties",
      "    arg_names, **additional_args)",
      "  File \"RECIPE_REPO[recipe_engine]/recipe_engine/internal/property_invoker.py\", in _invoke_with_properties",
      "    prop.interpret(all_props.get(prop_name, PROPERTY_SENTINEL), environ))",
      "  File \"RECIPE_REPO[recipe_engine]/recipe_engine/recipe_api.py\", in interpret",
      "    self.name, self.__property_type, self.full_decl_name))",
      "ValueError: No default specified and no value provided for 'task_name' from recipe 'flutter::devicelab'"
    ]
  },
  {
    "failure": {
      "humanReason": "Uncaught Exception: ValueError(\"No default specified and no value provided for 'task_name' from recipe 'flutter::devicelab'\",)"
    },
    "name": "$result"
  }
]