[
  {
    "cmd": [],
    "name": "RECIPE CRASH (Uncaught exception)",
    "~followup_annotations": [
      "@@@STEP_EXCEPTION@@@",
      "The recipe has crashed at point 'Uncaught exception'!",
      "",
      "Traceback (most recent call last):",
      "  File \"RECIPE_REPO[recipe_engine]/recipe_engine/internal/engine.py\", in run_steps",
      "    raw_result = recipe_obj.run_steps(api, engine)",
      "  File \"RECIPE_REPO[recipe_engine]/recipe_engine/internal/recipe_deps.py\", in run_steps",
      "    properties_def, api=api)",
      "  File \"RECIPE_REPO[recipe_engine]/recipe_engine/internal/property_invoker.py\", in invoke_with_properties",
      "    arg_names, **additional_args)",
      "  File \"RECIPE_REPO[recipe_engine]/recipe_engine/internal/property_invoker.py\", in _invoke_with_properties",
      "    return callable_obj(*props, **additional_args)",
      "  File \"RECIPE_REPO[flutter]/recipe_modules/repo_util/examples/unsupported.py\", line 15, in RunSteps",
      "    api.path['start_dir'].join('unsupported_repo'))",
      "  File \"RECIPE_REPO[recipe_engine]/recipe_engine/recipe_api.py\", in _inner",
      "    return func(*a, **kw)",
      "  File \"RECIPE_REPO[flutter]/recipe_modules/repo_util/api.py\", line 91, in checkout",
      "    raise ValueError('Unsupported repo: %s' % name)",
      "ValueError: Unsupported repo: unsupported_repo"
    ]
  },
  {
    "failure": {
      "humanReason": "Uncaught Exception: ValueError('Unsupported repo: unsupported_repo',)"
    },
    "name": "$result"
  }
]